Workbook

Sheet ESCUELITAS
A1: RESUMEN DE PAGOS PARA CADA UNO
C4: EL NORTE | J4: =+I9*30000 -> 6510000 | L4: =+L9 -> 5800000
C5: LIGA | F5: =+F9 -> 77220000 | H5: =-H9 -> -440000
N7: =SUM(N12:N44) -> 0
C8: Cant de trofeos | D8: 1900 | I8: =+I9*2 -> 434
C9: Cantidades | D9: =SUM(D12:D44) -> 1382 | E9: =SUM(E12:E44) -> 1372 | F9: =SUM(F12:F44) -> 77220000 | G9: =SUM(G12:G44) -> 10 | H9: =SUM(H12:H44) -> 440000 | I9: =SUM(I12:I44) -> 217 | J9: =SUM(J12:J44) -> 6510000 | K9: =SUM(K12:K44) -> 58 | ... P9: =SUM(P12:P44) -> 39330000
C10: ESCUELITA | D10: TROFEOS | E10: TORNEO | G10: LIBERADOS | H10: BONIF. | I10: Almuerzos 30,000 | K10: Torneo con Alojamiento 100,000 | M10: ALMUERZO PROFES | O10: TOTAL | P10: SALDO | Q10: PAGOS | Z10: GUILLE | AA10: DIEGO | AB10: FERNANDO
A11: # | B11: CC | D11: Cant | E11: Cant | F11: Importe | G11: Cant | H11: Importe | I11: Cant | J11: Importe | K11: Cant | L11: Importe | M11: Cant | N11: Importe | O11: Importe | P11: Importe | Q11: Importe 1 | R11: Destino | S11: Importe 2 | T11: Destino | U11: importe3 | V11: Destino | W11: Importe 3 | X11: Destino
A12: 1 | B12: 1 | C12: LOBITOS | D12: =+E12 -> 85 | E12: 85 | L12: =+K12*Precios!$C$7 -> 0 | Z12: =+SUMIFS(Q12:Q44,R12:R44,Z10)+SUMIFS(S12:S44,T12:T44,Z10)+SUMIFS(U12:U44,V12:V44,Z10)+SUMIFS(W12:W44,X12:X44,Z10) -> 17220000 | AA12: =+SUMIFS(Q12:Q44,R12:R44,AA10)+SUMIFS(S12:S44,T12:T44,AA10)+SUMIFS(U12:U44,V12:V44,AA10)+SUMIFS(W12:W44,X12:X44,AA10) -> 11810000 | AB12: =+SUMIFS(Q12:Q44,R12:R44,AB10)+SUMIFS(S12:S44,T12:T44,AB10)+SUMIFS(U12:U44,V12:V44,AB10)+SUMIFS(W12:W44,X12:X44,AB10) -> 3320000
A13: 2 | B13: 1 | C13: SAN PABLO | D13: =+E13 -> 0 | J13: =+I13*Precios!$C$6 -> 0 | L13: =+K13*Precios!$C$7 -> 0
A14: 3 | B14: 2 | C14: ACADEMIA SUR | D14: =+E14+G14 -> 90 | E14: 85 | F14: =+E14*Precios!$C$5 -> 5100000 | G14: 5 | J14: =+I14*Precios!$C$6 -> 0 | L14: =+K14*Precios!$C$7 -> 0 | M14: 0 | N14: =+M14*Precios!$C$8 -> 0 | O14: =+F14+J14+L14+N14-H14 -> 5100000 | P14: =+O14-(Q14+S14+W14+U14) -> 150000 | Q14: 2600000 | R14: EL NORTE | S14: 2350000 | T14: EL NORTE | W14: 0
A15: 4 | B15: 2 | C15: AMP. ALTAMIRA | D15: =+E15+G15 -> 47 | E15: 47 | F15: =+E15*Precios!$C$5 -> 2820000 | J15: =+I15*Precios!$C$6 -> 0 | L15: =+K15*Precios!$C$7 -> 0 | M15: 0 | N15: =+M15*Precios!$C$8 -> 0 | O15: =+F15+J15+L15+N15-H15 -> 2820000 | P15: =+O15-(Q15+S15+W15+U15) -> -60000 | Q15: =1080000+1800000 -> 2880000 | R15: ARBITRO CAÑA | S15: 0
A16: 5 | B16: 2 | C16: ARGENTINO JRS | D16: =+E16+G16 -> 44 | E16: 44 | F16: =+E16*Precios!$C$5 -> 2640000 | J16: =+I16*Precios!$C$6 -> 0 | L16: =+K16*Precios!$C$7 -> 0 | M16: 0 | N16: =+M16*Precios!$C$8 -> 0 | O16: =+F16+J16+L16+N16-H16 -> 2640000 | P16: =+O16-(Q16+S16+W16+U16) -> 2640000 | Q16: 0 | S16: 0 | W16: 0
A17: 6 | B17: 2 | C17: ATL. VILLA ALLENDE | D17: =+E17+G17 -> 40 | E17: 40 | F17: =+E17*Precios!$C$5 -> 2400000 | I17: 40 | J17: =+I17*Precios!$C$6 -> 1200000 | L17: =+K17*Precios!$C$7 -> 0 | M17: 0 | N17: =+M17*Precios!$C$8 -> 0 | O17: =+F17+J17+L17+N17-H17 -> 3600000 | P17: =+O17-(Q17+S17+W17+U17) -> 0 | Q17: 3600000 | R17: GUILLE | S17: 0 | W17: 0
A18: 7 | B18: 2 | C18: B° PARQUE | D18: =+E18+G18 -> 78 | E18: 78 | F18: =+E18*Precios!$C$5 -> 4680000 | I18: 78 | J18: =+I18*Precios!$C$6 -> 2340000 | L18: =+K18*Precios!$C$7 -> 0 | M18: 0 | N18: =+M18*Precios!$C$8 -> 0 | O18: =+F18+J18+L18+N18-H18 -> 7020000 | P18: =+O18-(Q18+S18+W18+U18) -> 3020000 | Q18: 4000000 | R18: DIEGO | S18: 0 | W18: 0
A19: 8 | B19: 2 | C19: CBA TALENTOS | D19: =+E19+G19 -> 0 | F19: =+E19*Precios!$C$5 -> 0 | J19: =+I19*Precios!$C$6 -> 0 | L19: =+K19*Precios!$C$7 -> 0 | M19: 0 | N19: =+M19*Precios!$C$8 -> 0 | O19: =+F19+J19+L19+N19-H19 -> 0 | P19: =+O19-(Q19+S19+W19+U19) -> -1740000 | Q19: =260000+630000+470000 -> 1360000 | R19: PARAMEDICOS UNC | S19: 380000 | T19: GUILLE | W19: 0
A20: 9 | B20: 2 | C20: D.I.E.F | D20: =+E20+G20 -> 141 | E20: 141 | F20: =+E20*Precios!$C$5 -> 8460000 | J20: =+I20*Precios!$C$6 -> 0 | L20: =+K20*Precios!$C$7 -> 0 | M20: 0 | N20: =+M20*Precios!$C$8 -> 0 | O20: =+F20+J20+L20+N20-H20 -> 8460000 | P20: =+O20-(Q20+S20+W20+U20) -> 8460000 | Q20: 0 | S20: 0 | W20: 0
A21: 10 | B21: 2 | C21: DANTE ALIGHERI | D21: =+E21+G21 -> 49 | E21: 49 | F21: =+E21*Precios!$C$5 -> 2940000 | J21: =+I21*Precios!$C$6 -> 0 | K21: 49 | L21: =+K21*Precios!$C$7 -> 4900000 | M21: 0 | N21: =+M21*Precios!$C$8 -> 0 | O21: =+F21+J21+L21+N21-H21 -> 7840000 | P21: =+O21-(Q21+S21+W21+U21) -> 4840000 | Q21: 3000000 | R21: GUILLE | S21: 0 | W21: 0
A22: 11 | B22: 2 | C22: EFUL | D22: =+E22+G22 -> 25 | E22: =9+16 -> 25 | F22: =+E22*Precios!$C$5 -> 1500000 | J22: =+I22*Precios!$C$6 -> 0 | K22: 9 | L22: =+K22*Precios!$C$7 -> 900000 | M22: 0 | N22: =+M22*Precios!$C$8 -> 0 | O22: =+F22+J22+L22+N22-H22 -> 2400000 | P22: =+O22-(Q22+S22+W22+U22) -> -410000 | Q22: 1350000 | R22: DIEGO | S22: 1460000 | T22: GUILLE | W22: 0
A23: 12 | B23: 2 | C23: EL TALADRO | D23: =+E23+G23 -> 66 | E23: =13*4+14 -> 66 | F23: =+E23*Precios!$C$5 -> 3960000 | J23: =+I23*Precios!$C$6 -> 0 | L23: =+K23*Precios!$C$7 -> 0 | M23: 0 | N23: =+M23*Precios!$C$8 -> 0 | O23: =+F23+J23+L23+N23-H23 -> 3960000 | P23: =+O23-(Q23+S23+W23+U23) -> 240000 | Q23: =1200000+2520000 -> 3720000 | R23: ARBITRO CAÑA | S23: 0 | W23: 0
A24: 13 | B24: 2 | C24: ESTRELLA AZUL | D24: =+E24+G24 -> 15 | E24: 15 | F24: =+E24*Precios!$C$5 -> 900000 | J24: =+I24*Precios!$C$6 -> 0 | L24: =+K24*Precios!$C$7 -> 0 | M24: 0 | N24: =+M24*Precios!$C$8 -> 0 | O24: =+F24+J24+L24+N24-H24 -> 900000 | P24: =+O24-(Q24+S24+W24+U24) -> 0 | Q24: 900000 | R24: AMBULANCIA SEM | S24: 0 | W24: 0
A25: 14 | B25: 2 | C25: ESTRELLAS SUR | D25: =+E25+G25 -> 60 | E25: 60 | F25: =+E25*Precios!$C$5 -> 3600000 | J25: =+I25*Precios!$C$6 -> 0 | L25: =+K25*Precios!$C$7 -> 0 | M25: 0 | N25: =+M25*Precios!$C$8 -> 0 | O25: =+F25+J25+L25+N25-H25 -> 3600000 | P25: =+O25-(Q25+S25+W25+U25) -> 600000 | Q25: 3000000 | R25: DIEGO | S25: 0 | W25: 0
A26: 15 | B26: 2 | C26: FELIPA | D26: =+E26+G26 -> 0 | E26: 0 | F26: =+E26*Precios!$C$5 -> 0 | J26: =+I26*Precios!$C$6 -> 0 | L26: =+K26*Precios!$C$7 -> 0 | M26: 0 | N26: =+M26*Precios!$C$8 -> 0 | O26: =+F26+J26+L26+N26-H26 -> 0 | P26: =+O26-(Q26+S26+W26+U26) -> -1000000 | Q26: 1000000 | R26: GUILLE | S26: 0 | W26: 0
A27: =+A26+1 -> 16 | B27: 2 | C27: INSTITUTO | D27: =+E27+G27 -> 60 | E27: 60 | F27: =+E27*Precios!$C$5 -> 3600000 | H27: =5*60000 -> 300000 | J27: =+I27*Precios!$C$6 -> 0 | L27: =+K27*Precios!$C$7 -> 0 | M27: 0 | N27: =+M27*Precios!$C$8 -> 0 | O27: =+F27+J27+L27+N27-H27 -> 3300000 | P27: =+O27-(Q27+S27+W27+U27) -> 660000 | Q27: 2640000 | R27: FERNANDO | S27: 0 | W27: 0
A28: =+A27+1 -> 17 | B28: 2 | C28: KABALLS | D28: =+E28+G28 -> 15 | E28: 15 | F28: =+E28*Precios!$C$5 -> 900000 | J28: =+I28*Precios!$C$6 -> 0 | L28: =+K28*Precios!$C$7 -> 0 | M28: 0 | N28: =+M28*Precios!$C$8 -> 0 | O28: =+F28+J28+L28+N28-H28 -> 900000 | P28: =+O28-(Q28+S28+W28+U28) -> 240000 | Q28: =260000+400000 -> 660000 | R28: DIEGO | S28: 0 | W28: 0
A29: =+A28+1 -> 18 | B29: 2 | C29: LA LOMITA | D29: =+E29+G29 -> 0 | F29: =+E29*Precios!$C$5 -> 0 | J29: =+I29*Precios!$C$6 -> 0 | L29: =+K29*Precios!$C$7 -> 0 | M29: 0 | N29: =+M29*Precios!$C$8 -> 0 | O29: =+F29+J29+L29+N29-H29 -> 0 | P29: =+O29-(Q29+S29+W29+U29) -> -2000000 | Q29: =1000000+1000000 -> 2000000 | R29: DIEGO | S29: 0 | W29: 0
A30: =+A29+1 -> 19 | B30: 2 | C30: LASALLANO | D30: =+E30+G30 -> 95 | E30: 95 | F30: =+E30*Precios!$C$5 -> 5700000 | J30: =+I30*Precios!$C$6 -> 0 | L30: =+K30*Precios!$C$7 -> 0 | M30: 0 | N30: =+M30*Precios!$C$8 -> 0 | O30: =+F30+J30+L30+N30-H30 -> 5700000 | P30: =+O30-(Q30+S30+W30+U30) -> 5700000 | Q30: 0 | S30: 0 | W30: 0
A31: =+A30+1 -> 20 | B31: 2 | C31: LE.CE.FI | D31: =+E31+G31 -> 0 | F31: =+E31*Precios!$C$5 -> 0 | J31: =+I31*Precios!$C$6 -> 0 | L31: =+K31*Precios!$C$7 -> 0 | M31: 0 | N31: =+M31*Precios!$C$8 -> 0 | O31: =+F31+J31+L31+N31-H31 -> 0 | P31: =+O31-(Q31+S31+W31+U31) -> 0 | Q31: 0 | S31: 0 | W31: 0
A32: =+A31+1 -> 21 | B32: 2 | C32: MITO DIAZ | D32: =+E32+G32 -> 0 | F32: =+E32*Precios!$C$5 -> 0 | J32: =+I32*Precios!$C$6 -> 0 | L32: =+K32*Precios!$C$7 -> 0 | M32: 0 | N32: =+M32*Precios!$C$8 -> 0 | O32: =+F32+J32+L32+N32-H32 -> 0 | P32: =+O32-(Q32+S32+W32+U32) -> 0 | Q32: 0 | S32: 0 | W32: 0
A33: =+A32+1 -> 22 | B33: 2 | C33: POL. Va DEL ROSARIO | D33: =+E33+G33 -> 0 | F33: =+E33*Precios!$C$5 -> 0 | J33: =+I33*Precios!$C$6 -> 0 | L33: =+K33*Precios!$C$7 -> 0 | M33: 0 | N33: =+M33*Precios!$C$8 -> 0 | O33: =+F33+J33+L33+N33-H33 -> 0 | P33: =+O33-(Q33+S33+W33+U33) -> -180000 | Q33: 180000 | R33: FERNANDO | S33: 0 | W33: 0
A34: =+A33+1 -> 23 | B34: 2 | C34: RACING | D34: =+E34+G34 -> 67 | E34: 67 | F34: =+E34*Precios!$C$5 -> 4020000 | J34: =+I34*Precios!$C$6 -> 0 | L34: =+K34*Precios!$C$7 -> 0 | M34: 0 | N34: =+M34*Precios!$C$8 -> 0 | O34: =+F34+J34+L34+N34-H34 -> 4020000 | P34: =+O34-(Q34+S34+W34+U34) -> 4020000 | Q34: 0 | S34: 0 | W34: 0
A35: =+A34+1 -> 24 | B35: 2 | C35: RIVER PLATE | D35: =+E35+G35 -> 49 | E35: 49 | F35: =+E35*Precios!$C$5 -> 2940000 | H35: 140000 | J35: =+I35*Precios!$C$6 -> 0 | L35: =+K35*Precios!$C$7 -> 0 | M35: 0 | N35: =+M35*Precios!$C$8 -> 0 | O35: =+F35+J35+L35+N35-H35 -> 2800000 | P35: =+O35-(Q35+S35+W35+U35) -> 0 | Q35: 2800000 | R35: TROFEOS | S35: 0 | W35: 0
A36: =+A35+1 -> 25 | B36: 2 | C36: RANCAGUA | D36: =+E36+G36 -> 0 | F36: =+E36*Precios!$C$5 -> 0 | J36: =+I36*Precios!$C$6 -> 0 | L36: =+K36*Precios!$C$7 -> 0 | M36: 0 | N36: =+M36*Precios!$C$8 -> 0 | O36: =+F36+J36+L36+N36-H36 -> 0 | P36: =+O36-(Q36+S36+W36+U36) -> -200000 | Q36: 200000 | R36: FERNANDO | S36: 0 | W36: 0
A37: =+A36+1 -> 26 | B37: 2 | C37: ROBLES | D37: =+E37+G37 -> 0 | F37: =+E37*Precios!$C$5 -> 0 | J37: =+I37*Precios!$C$6 -> 0 | L37: =+K37*Precios!$C$7 -> 0 | M37: 0 | N37: =+M37*Precios!$C$8 -> 0 | O37: =+F37+J37+L37+N37-H37 -> 0 | P37: =+O37-(Q37+S37+W37+U37) -> 0 | Q37: 0 | S37: 0 | W37: 0
A38: =+A37+1 -> 27 | B38: 2 | C38: STOECKLIN | D38: =+E38+G38 -> 0 | F38: =+E38*Precios!$C$5 -> 0 | J38: =+I38*Precios!$C$6 -> 0 | L38: =+K38*Precios!$C$7 -> 0 | M38: 0 | N38: =+M38*Precios!$C$8 -> 0 | O38: =+F38+J38+L38+N38-H38 -> 0 | P38: =+O38-(Q38+S38+W38+U38) -> 0 | Q38: 0 | S38: 0 | W38: 0
A39: =+A38+1 -> 28 | B39: 2 | C39: TALENTO DEP. | D39: =+E39+G39 -> 75 | E39: 75 | F39: =+E39*Precios!$C$5 -> 4500000 | I39: 75 | J39: =+I39*Precios!$C$6 -> 2250000 | L39: =+K39*Precios!$C$7 -> 0 | M39: 0 | N39: =+M39*Precios!$C$8 -> 0 | O39: =+F39+J39+L39+N39-H39 -> 6750000 | P39: =+O39-(Q39+S39+W39+U39) -> 3190000 | Q39: 3560000 | R39: GUILLE | S39: 0 | W39: 0
A40: =+A39+1 -> 29 | B40: 2 | C40: TALLERES BOTANICO | D40: =+E40+G40 -> 35 | E40: =23+12 -> 35 | F40: =+E40*Precios!$C$5 -> 2100000 | I40: 24 | J40: =+I40*Precios!$C$6 -> 720000 | L40: =+K40*Precios!$C$7 -> 0 | M40: 0 | N40: =+M40*Precios!$C$8 -> 0 | O40: =+F40+J40+L40+N40-H40 -> 2820000 | P40: =+O40-(Q40+S40+W40+U40) -> 0 | Q40: 300000 | R40: FERNANDO | S40: =990000+1500000+30000 -> 2520000 | T40: GUILLE | W40: 0
A41: =+A40+1 -> 30 | B41: 2 | C41: TALLERES S.V | D41: =+E41+G41 -> 95 | E41: 95 | F41: =+E41*Precios!$C$5 -> 5700000 | J41: =+I41*Precios!$C$6 -> 0 | L41: =+K41*Precios!$C$7 -> 0 | M41: 0 | N41: =+M41*Precios!$C$8 -> 0 | O41: =+F41+J41+L41+N41-H41 -> 5700000 | P41: =+O41-(Q41+S41+W41+U41) -> 5700000 | Q41: 0 | S41: 0 | W41: 0
A42: =+A41+1 -> 31 | B42: 2 | C42: TALLERES V. RETIRO | D42: =+E42+G42 -> 61 | E42: 61 | F42: =+E42*Precios!$C$5 -> 3660000 | J42: =+I42*Precios!$C$6 -> 0 | L42: =+K42*Precios!$C$7 -> 0 | M42: 0 | N42: =+M42*Precios!$C$8 -> 0 | O42: =+F42+J42+L42+N42-H42 -> 3660000 | P42: =+O42-(Q42+S42+W42+U42) -> 3660000 | Q42: 0 | S42: 0 | W42: 0
A43: =+A42+1 -> 32 | B43: 2 | C43: TALLERES YOFRE | D43: =+E43+G43 -> 0 | F43: =+E43*Precios!$C$5 -> 0 | J43: =+I43*Precios!$C$6 -> 0 | L43: =+K43*Precios!$C$7 -> 0 | M43: 0 | N43: =+M43*Precios!$C$8 -> 0 | O43: =+F43+J43+L43+N43-H43 -> 0 | P43: =+O43-(Q43+S43+W43+U43) -> -2500000 | Q43: 800000 | R43: ARBITRO CAÑA | S43: 1700000 | T43: GUILLE | W43: 0
...

Sheet INGRESOS-EGRESOS
C2: INGRESOS TORNEO | D2: CANT | E2: Importe
C3: STAND BASE | D3: 1 | E3: =+Precios!C11 -> 700000
C4: STAND POCHOCLO | D4: 1 | E4: =+Precios!C12 -> 400000
C5: STAND TATU | D5: 1 | E5: =+Precios!C13 -> 100000
C7: INGRESOS EL NORTE | D7: CANT | E7: Importe | G7: =SUM(E8:E9) -> 0
C8: ENTRADAS
C9: ALOJAMIENTOS
J11: =+H27+H48+H62+H65+H67+J65+J78+H78+H96 -> 1727500
C12: EGRESOS EL NORTE
C13: BOLETEROS
C14: GUARDIAS- FULVIO (LIGA)
C15: GUARDIAS - MARCOS
C16: TICKETS- LIBRERIA - TALONARIOS
E19: =SUM(E22:E56) -> 36594000 | F19: =SUM(F22:F56) -> 13184000 | G19: =SUM(G22:G56) -> 23410000
C20: EGRESOS TORNEO | D20: Cant | E20: Importe | F20: Pago | G20: Saldo | H20: Pago | I20: CREDITO 1 | J20: Pago | K20: CREDITO 2 | L20: Pago | M20: CREDITO 3 | N20: Pago | O20: CREDITO 3 | Q20: GUILLE | R20: DIEGO | S20: FERNANDO
C21: TORNEO
B22: 1 | C22: ARBITROS 1 | F22: =+H22+J22+L22 -> 0 | G22: =+E22-F22 -> 0 | Q22: =+SUMIFS(H22:H126,I22:I126,Q20)+SUMIFS(J22:J126,K22:K126,Q20)+SUMIFS(L22:L126,M22:M126,Q20)+SUMIFS(N22:N126,O22:O126,Q20) -> 2849000 | R22: =+SUMIFS(H22:H133,I22:I133,R20)+SUMIFS(J22:J133,K22:K133,R20)+SUMIFS(L22:L133,M22:M133,R20)+SUMIFS(N22:N133,O22:O133,R20) -> 1635000 | S22: =+SUMIFS(H22:H138,I22:I138,S20)+SUMIFS(J22:J138,K22:K138,S20)+SUMIFS(L22:L138,M22:M138,S20)+SUMIFS(N22:N138,O22:O138,S20) -> 0
A23: 275000 | B23: 1 | C23: ARBITROS FACU | D23: 6 | E23: =+A23*D23 -> 1650000 | F23: =+H23+J23+L23 -> 0 | G23: =+E23-F23 -> 1650000
A24: 275000 | B24: 1 | C24: ARBITROS CAÑA | D24: 32 | E24: =+A24*D24 -> 8800000 | F24: =+H24+J24+L24 -> 7400000 | G24: =+E24-F24 -> 1400000 | H24: =1200000+2520000 -> 3720000 | I24: EL TALADRO | J24: 800000 | K24: TALLERES YOFRE | L24: =1080000+1800000 -> 2880000 | M24: AMP. ALTAMIRA
A25: 280000 | B25: 1 | C25: ARBITROS PABLITO | D25: 9 | E25: =+A25*D25 -> 2520000 | F25: =+H25+J25+L25 -> 0 | G25: =+E25-F25 -> 2520000
B26: 1 | C26: AYUDANTE - VIERNES | F26: =+H26+J26+L26 -> 0 | G26: =+E26-F26 -> 0
B27: 1 | C27: BANDERAS | D27: 25 | E27: 330000 | F27: =+H27+J27+L27 -> 330000 | G27: =+E27-F27 -> 0 | H27: 330000 | I27: GUILLE
B28: 1 | C28: HIERROS PARA DIVIDIR CANCHAS | E28: 90000 | F28: =+H28+J28+L28 -> 90000 | G28: =+E28-F28 -> 0 | H28: 90000 | I28: GUILLE
B29: 1 | C29: BEBIDAS- GENERAL | F29: =+H29+J29+L29 -> 0 | G29: =+E29-F29 -> 0
B30: 1 | C30: BEBIDAS PARAMEDICOS | F30: =+H30+J30+L30 -> 0 | G30: =+E30-F30 -> 0
B31: 1 | C31: CARTEL | E31: 290000 | F31: =+H31+J31+L31 -> 0 | G31: =+E31-F31 -> 290000
B32: 1 | C32: CRISTIAN ABRANCHI | F32: =+H32+J32+L32 -> 0 | G32: =+E32-F32 -> 0
B33: 1 | C33: CROSTI | F33: =+H33+J33+L33 -> 0 | G33: =+E33-F33 -> 0
B34: 1 | C34: FLETE- ARCOS | E34: 800000 | F34: =+H34+J34+L34 -> 400000 | G34: =+E34-F34 -> 400000 | H34: 400000 | I34: GUILLE
B35: 1 | C35: LUIS TRASLADOS ARCOS | E35: 50000 | F35: =+H35+J35+L35 -> 50000 | G35: =+E35-F35 -> 0 | H35: 50000 | I35: GUILLE
B36: 1 | C36: FACU TRASLADOS ARCOS | E36: 50000 | F36: =+H36+J36+L36 -> 50000 | G36: =+E36-F36 -> 0 | H36: 50000 | I36: GUILLE
B37: 1 | C37: ARMADO DE CANCHAS | E37: 300000 | F37: =+H37+J37+L37 -> 300000 | G37: =+E37-F37 -> 0 | H37: 300000 | I37: GUILLE
B38: 1 | C38: FLETE- TROFEOS | F38: =+H38+J38+L38 -> 0 | G38: =+E38-F38 -> 0
B39: 1 | C39: FUTBOL | E39: 900000 | F39: =+H39+J39+L39 -> 900000 | G39: =+E39-F39 -> 0 | H39: 900000 | I39: DIEGO
B40: 1 | C40: GONZALO Y OSO | F40: =+H40+J40+L40 -> 0 | G40: =+E40-F40 -> 0
B41: 1 | C41: GUANCHITO | F41: =+H41+J41+L41 -> 0 | G41: =+E41-F41 -> 0
B42: 1 | C42: GUANCHOPE | F42: =+H42+J42+L42 -> 0 | G42: =+E42-F42 -> 0
B43: 1 | C43: JAVI LASCANO | F43: =+H43+J43+L43 -> 0 | G43: =+E43-F43 -> 0
B44: 1 | C44: LUISITO | F44: =+H44+J44+L44 -> 0 | G44: =+E44-F44 -> 0
B45: 1 | C45: MATU LASCANO | F45: =+H45+J45+L45 -> 0 | G45: =+E45-F45 -> 0
...

Sheet NEGOCIADOS- EL NORTE
D1: MUNDIALITO - LIGA PARTICIPANDO - AGOSTO 2026
D4: BALANCE "BOLETERIA"
D6: INGRESOS | E6: Cant | F6: Pu | G6: TOTAL
D7: SABADO
D8: ENTRADAS | F8: 5000 | G8: =+E8*F8 -> 0
D9: AUTOS | F9: 5000 | G9: =+E9*F9 -> 0
D11: DOMINGO
D12: ENTRADAS | F12: 5000 | G12: =+E12*F12 -> 0
D13: AUTOS | F13: 5000 | G13: =+E13*F13 -> 0
D16: SUB TOTAL INGRESOS "BOLETERIA" | G16: =+G8+G9+G12+G13 -> 0
D19: EGRESOS | E19: Cant | F19: Pu | G19: IMPORTE | H19: TOTAL
D21: LIGA | H21: =+G22+G23+G24 -> 0
D22: GUARDIAS- FULVIO (LIGA)
D23: BOLETEROS
D24: TICKETS- LIBRERIA
D26: EL NORTE | H26: =+G27 -> 0
D27: GUARDIAS - MARCOS
D29: SUB-TOTAL EGRESOS "BOLETERIA" | H29: =+H21+H26 -> 0
D31: TOTAL BALANCE "BOLETERIA" | G31: =+G16-H29 -> 0
D33: DISTRIBUCION DE DIVIDENDOS | E33: =+G31/2 -> 0
D35: DIVIDENDOS Y REINTEGROS | E35: EGRESOS | F35: DIVIDENDO | G35: DISTRIBUCION
D37: EL NORTE | E37: =+H26 -> 0 | F37: =+E33 -> 0 | G37: =+E37+F37 -> 0
D38: LIGA | E38: =+H21 -> 0 | F38: =+F37 -> 0 | G38: =+F38+E38 -> 0
D42: BALANCE "ALOJAMIENTOS Y COMEDOR"
C45: DETALLE - COMEDOR | E45: Cant | H45: TOTAL
D46: SABADO - ALMUERZO | E46: =SUM(E47:E49) -> 317 | H46: =SUM(H47:H50) -> 16510000
D47: INSCRIPTOS (solo almuerzos) | E47: =+ESCUELITAS!I9 -> 217 | H47: =+ESCUELITAS!J9 -> 6510000
D48: INSCRIPTOS - ALOJADOS | E48: =+ESCUELITAS!K9 -> 58 | H48: =+ESCUELITAS!L9 -> 5800000
D49: ALOJADOS - DUPLEX | E49: =+DUPLEX!D8 -> 42 | H49: =+DUPLEX!E8 -> 4200000
D50: PROFES | E50: =+ESCUELITAS!M9 -> 0 | H50: 0
D52: SABADO - CENA | E52: =SUM(E53:E54) -> 100
D53: INSCRIPTOS - ALOJADOS | E53: =+E48 -> 58
D54: ALOJADOS - DUPLEX | E54: =+E49 -> 42
D55: PROFES | E55: =+E50 -> 0
D57: DOMINGO - DESAYUNO | E57: =SUM(E58:E59) -> 100
D58: INSCRIPTOS - ALOJADOS | E58: =+E53 -> 58
D59: ALOJADOS - DUPLEX | E59: =+E54 -> 42
D60: PROFES | E60: =+E55 -> 0
D62: DOMINGO - ALMUERZO | E62: =SUM(E63:E65) -> 317
D63: INSCRIPTOS (solo almuerzos) | E63: =+E47 -> 217
...

Sheet MAYOR
B2: CUENTAS A COBRAR
B4: TORNEO
B5: STAND
B6: COMISION EL NORTE
B7: BOLETERIA
B8: ALMUERZOS
B9: HOTEL
B10: DUPLEX
B12: CUENTAS A PAGAR | G12: =SUM(E14:E17) -> 45420960
B14: TORNEO | E14: =+'INGRESOS-EGRESOS'!G19+'INGRESOS-EGRESOS'!G60+'INGRESOS-EGRESOS'!G74+'INGRESOS-EGRESOS'!G90 -> 27440000
B15: BOLETERIA NORTE
B16: EL NORTE (ALM-ALO-DUP) | E16: =+'NEGOCIADOS- EL NORTE'!G116 -> 11560000
B17: FERNANDO | E17: =+'INGRESOS-EGRESOS'!G105 -> 6420960
B19: INGRESOS | G19: =SUM(D21:D24) -> 77980000
B21: TORNEO | D21: =+ESCUELITAS!F9-ESCUELITAS!H9 -> 76780000
B22: STAND | D22: =+DUPLEX!E34 -> 1200000
B23: COMISION EL NORTE
B24: BOLETERIA
B26: EGRESOS | G26: =SUM(D27:D32) -> 67574960
B27: TORNEO | D27: =+'INGRESOS-EGRESOS'!E19+'INGRESOS-EGRESOS'!E60+'INGRESOS-EGRESOS'!E74+'INGRESOS-EGRESOS'!E90 -> 44644000
B28: BOLETERIA NORTE | D28: 0
B29: ALMUERZOS NORTE | D29: =+'NEGOCIADOS- EL NORTE'!H47 -> 6510000
B30: HOTEL NORTE | D30: =+'NEGOCIADOS- EL NORTE'!H48 -> 5800000
B31: DUPLEX NORTE | D31: =+'NEGOCIADOS- EL NORTE'!H49 -> 4200000
B32: FERNANDO | D32: =+'INGRESOS-EGRESOS'!E105 -> 6420960

Sheet DUPLEX
H1: pagos al norte
H2: IMP TOTAL | I2: PAGOS | J2: SALDO
H3: =+E8 -> 4200000 | I3: 0 | J3: =+H3-I3 -> 4200000
D4: ALMUERZO | E4: 15000
D5: PRECIO | E5: =+Precios!C7 -> 100000
B8: TOTALES | D8: =SUM(D10:D29) -> 42 | E8: =SUM(E10:E29) -> 4200000 | F8: =SUM(F10:F29) -> 50000 | G8: =SUM(G10:G29) -> 4150000
B9: DUPLEX | C9: 01 - ORGANIZACIÓN 02 - INSCRIPTOS 03 - ALQUILER | D9: CANT / PERSONAS | E9: IMPORTE | F9: Pago | G9: Saldo | H9: Pago | I9: CREDITO 1 | J9: Pago | K9: CREDITO 2 | L9: Pago | M9: CREDITO 3 | O9: GUILLE | P9: DIEGO | Q9: FERNANDO
B10: 1 | C10: 1 | E10: 0 | F10: =+H10+J10+L10 -> 0 | G10: =+E10-F10 -> 0
B11: 2 | C11: 1 | O11: =SUMIFS(H12:H58,I12:I58,O9)+SUMIFS(J12:J58,K12:K58,O9)+SUMIFS(L12:L58,M12:M58,O9) -> 50000 | P11: =SUMIFS(H12:H58,I12:I58,P9)+SUMIFS(J12:J58,K12:K58,P9)+SUMIFS(L12:L58,M12:M58,P9) -> 0 | Q11: =SUMIFS(H12:H58,I12:I58,Q9)+SUMIFS(J12:J58,K12:K58,Q9)+SUMIFS(L12:L58,M12:M58,Q9) -> 0
B12: 3 | C12: 1
B13: 4 | C13: 1
A14: GUILLE | B14: 5 | C14: 3 | D14: 5 | E14: =+D14*100000 -> 500000 | F14: =+H14+J14+L14 -> 0 | G14: =+E14-F14 -> 500000
A15: AGOSTINA M. JOSE | B15: 6 | C15: 3 | D15: 5 | E15: =+D15*100000 -> 500000 | F15: =+H15+J15+L15 -> 0 | G15: =+E15-F15 -> 500000
A16: CAPELLETTI JORGE | B16: 7 | C16: 3 | D16: 0 | E16: =+D16*100000 -> 0 | F16: =+H16+J16+L16 -> 0 | G16: =+E16-F16 -> 0
A17: GALINDE MELIZA | B17: 8 | C17: 3 | D17: 0 | E17: =+D17*100000 -> 0 | F17: =+H17+J17+L17 -> 0 | G17: =+E17-F17 -> 0
A18: SCAVARDA CAROLINA | B18: 9 | C18: 3 | D18: 5 | E18: =+D18*100000 -> 500000 | F18: =+H18+J18+L18 -> 0 | G18: =+E18-F18 -> 500000
A19: LUCIANA GOULD | B19: 10 | C19: 3 | D19: 0 | E19: =+D19*100000 -> 0 | F19: =+H19+J19+L19 -> 0 | G19: =+E19-F19 -> 0
A20: ADAN RAM | B20: 11 | C20: 3 | D20: 4 | E20: =+D20*100000 -> 400000 | F20: =+H20+J20+L20 -> 0 | G20: =+E20-F20 -> 400000
A21: JOSE RODRIGUEZ | B21: 12 | C21: 3 | D21: 4 | E21: =+D21*100000 -> 400000 | F21: =+H21+J21+L21 -> 0 | G21: =+E21-F21 -> 400000
A22: SILVANA MACCIO | B22: 13 | C22: 3 | D22: 4 | E22: =+D22*100000 -> 400000 | F22: =+H22+J22+L22 -> 0 | G22: =+E22-F22 -> 400000
A23: JULIO MEDINA CAMPOS | B23: 14 | C23: 3 | D23: 5 | E23: =+D23*100000 -> 500000 | F23: =+H23+J23+L23 -> 50000 | G23: =+E23-F23 -> 450000 | H23: 50000 | I23: GUILLE
A24: BRASCA VALENTIN | B24: 15 | C24: 3 | D24: 5 | E24: =+D24*100000 -> 500000 | F24: =+H24+J24+L24 -> 0 | G24: =+E24-F24 -> 500000
A25: MELODI BARRIONUEVO | B25: 16 | C25: 3 | D25: 5 | E25: =+D25*100000 -> 500000 | F25: =+H25+J25+L25 -> 0 | G25: =+E25-F25 -> 500000
B26: 17
B27: 18
B28: 19
B29: 20
A34: STAND | E34: =SUM(E36:E38) -> 1200000 | G34: =SUM(G36:G38) -> 1200000
E35: IMPORTE | F35: PAGADO | G35: SALDO | H35: Pago | I35: CREDITO 1 | J35: Pago | K35: CREDITO 2 | L35: Pago | M35: CREDITO 3
A36: STAND BASE | E36: 700000 | F36: 0 | G36: =+E36-F36 -> 700000
A37: STAND POCHOCLO | E37: 400000 | F37: =+H37+J37+L37 -> 0 | G37: =+E37-F37 -> 400000
A38: STAND TATU | E38: 100000 | F38: 0 | G38: =+E38-F38 -> 100000

Sheet Precios
B4: CONCEPTO | C4: C/U
B5: Inscripcion | C5: 60000
B6: 2 ALMUERZOS | C6: 30000
B7: Alojamiento | C7: 100000
B8: Almuerzo Profes | C8: 17000
B9: Entradas | C9: 5000
B10: Estacionamientos | C10: 5000
B11: STAND BASE | C11: 700000
B12: STAND POCHOCLO | C12: 400000
B13: STAND TATU | C13: 100000

Sheet RECIBOS
A2: SERVICIOS
A3: DESAYUNO | B3: ALMUERZO | C3: CENA | D3: 100 | E3: Escuela de Futbol | F3: CANTIDAD | G3: MONTO | H3: IMP.TOTAL
E5: Torneo | F5: 100 | G5: 1000 | H5: =+F5*G5 -> 100000
B6: 2 | D6: 2 | E6: Almuerzos | F6: 40 | G6: 2000 | H6: =+F6*G6 -> 80000
A7: 1 | B7: 2 | C7: 1 | D7: 2 | E7: Torneo con Alojamiento | F7: 20 | G7: 5000 | H7: =+F7*G7 -> 100000
E8: Sub Total 1 | F8: =SUM(F5:F7) -> 160 | H8: =SUM(H5:H7) -> 280000
E10: ALMUERZOS PROFES | F10: 25 | G10: 17000 | H10: =+F10*G10 -> 425000
E12: TOTAL GRAL | H12: =+H10+H8 -> 705000
E14: TROFEOS
E15: Torneo | F15: 100
E16: Liberados | F16: 3
E17: TICKETS ALMUERZO | F17: 3
E20: RECIBO | F20: EFECTIVO | G20: TRANSF | H20: CANJE
E21: GUILLE | F21: 5000
E22: DIEGO | F22: 200
E23: FER
E24: EL NORTE
E25: PARAMEDICOS | F25: 5000
E26: AMBULANCIA
E27: ARBITROS CAÑA | F27: 6000
E28: OTROS

Sheet TROFEOS

Sheet CENTRO DE COSTOS
B2: TORNEO | C2: BOLETERIA | D2: STANDS | E2: ALOJAMIENTOS
A3: INGRESOS
A4: GASTOS
A6: TOTALES

Sheet BALANCE
N1: =+N2-O2 -> 12620000
N2: =+N4+N9+N15+N29+N35 -> 146795960 | O2: =+O4+O9+O15+O29+O35 -> 134175960
F3: D | G3: H | N3: D | O3: H | P3: SALDO
C4: CAJA | K4: CAJA | N4: =SUM(N5:N7) -> 32400000 | O4: =SUM(O5:O7) -> 4484000 | P4: =+N4-O4 -> 27916000
D5: GUILLE | F5: =+DIVIDENDOS!E4 -> 14421000 | L5: GUILLE | N5: =+DIVIDENDOS!C4 -> 17270000 | O5: =+DIVIDENDOS!D4 -> 2849000
D6: DIEGO | F6: =+DIVIDENDOS!E9 -> 10175000 | L6: DIEGO | N6: =+DIVIDENDOS!C9 -> 11810000 | O6: =+DIVIDENDOS!D9 -> 1635000
D7: FERNANDO | F7: =+DIVIDENDOS!E16 -> 3320000 | L7: FERNANDO | N7: =+DIVIDENDOS!C16 -> 3320000 | O7: =+DIVIDENDOS!D16 -> 0
C9: A COBRAR | K9: A COBRAR | N9: =SUM(N10:N12) -> 42181000 | O9: =SUM(O10:O12) -> 0 | P9: =+N9-O9 -> 42181000
D10: TORNEO | F10: =+ESCUELITAS!P9 -> 39330000 | L10: TORNEO | N10: =+ESCUELITAS!P9 -> 39330000
D11: STAND | F11: =+DUPLEX!G34 -> 1200000 | L11: STAND | N11: =+DUPLEX!G34 -> 1200000
D12: EL NORTE | F12: =+'NEGOCIADOS- EL NORTE'!H86 -> 4950000 | L12: EL NORTE COMIS ALOJA | N12: =+'NEGOCIADOS- EL NORTE'!G118 -> 1651000
C15: A PAGAR | K15: A PAGAR | N15: =SUM(N16:N23) -> 0 | O15: =SUM(O16:O23) -> 49620960 | P15: =+O15-N15 -> 49620960
D16: TORNEO | G16: =+'INGRESOS-EGRESOS'!G19 -> 23410000 | L16: TORNEO | O16: =+'INGRESOS-EGRESOS'!G19 -> 23410000
D17: SERVICIOS | G17: =+'INGRESOS-EGRESOS'!G74 -> 4030000 | L17: SERVICIOS | O17: =+'INGRESOS-EGRESOS'!G74 -> 4030000
D18: LIBRERIA | G18: =+'INGRESOS-EGRESOS'!G60 -> 0 | L18: LIBRERIA | O18: =+'INGRESOS-EGRESOS'!G60 -> 0
D19: VIATICOS | G19: =+'INGRESOS-EGRESOS'!G90 -> 0 | L19: VIATICOS | O19: =+'INGRESOS-EGRESOS'!G90 -> 0
D20: FERNANDO | G20: =+'INGRESOS-EGRESOS'!G105 -> 6420960 | L20: FERNANDO | O20: =+'INGRESOS-EGRESOS'!G105 -> 6420960
L21: EL NORTE- DUPLEX | O21: =+DUPLEX!J3 -> 4200000
L22: EL NORTE- ENTRADAS | O22: 0
L23: EL NORTE - ALOJAMIENTOS | O23: =+'NEGOCIADOS- EL NORTE'!G116 -> 11560000
K25: AJUSTE TECNICO
C26: INGRESOS
D27: TORNEO | G27: =+ESCUELITAS!O9 -> 89090000
D28: STAND | G28: =+DUPLEX!E34 -> 1200000
D29: EL NORTE | G29: =+'NEGOCIADOS- EL NORTE'!F76 -> 1651000 | K29: INGRESOS | N29: =SUM(N30:N33) -> 440000 | O29: =SUM(O30:O33) -> 80071000 | P29: =+O29-N29 -> 79631000
D30: BOLETERIA | G30: =+'NEGOCIADOS- EL NORTE'!E33 -> 0 | L30: TORNEO | N30: =+ESCUELITAS!H9 -> 440000 | O30: =+ESCUELITAS!F9 -> 77220000
L31: STAND | O31: =+DUPLEX!E34 -> 1200000
C32: EGRESOS | L32: EL NORTE COMIS ALOJA | O32: =+'NEGOCIADOS- EL NORTE'!F76 -> 1651000
D33: TORNEO | F33: =+'INGRESOS-EGRESOS'!E19 -> 36594000 | L33: BOLETERIA | O33: 0
D34: SERVICIOS | F34: =+'INGRESOS-EGRESOS'!E74 -> 7217000
D35: LIBRERIA | F35: =+'INGRESOS-EGRESOS'!E60 -> 793000 | K35: EGRESOS | N35: =SUM(N36:N43) -> 71774960 | O35: =SUM(O36:O43) -> 0 | P35: =+N35-O35 -> 71774960
D36: VIATICOS | F36: =+'INGRESOS-EGRESOS'!E90 -> 40000 | L36: TORNEO | N36: =+'INGRESOS-EGRESOS'!E19 -> 36594000
D37: FERNANDO | F37: =+'INGRESOS-EGRESOS'!E105 -> 6420960 | L37: SERVICIOS | N37: =+'INGRESOS-EGRESOS'!E74 -> 7217000
D38: NORTE -ALOJAM. | L38: LIBRERIA | N38: =+'INGRESOS-EGRESOS'!E60 -> 793000
D39: NORTE- ENTRADAS | L39: VIATICOS | N39: =+'INGRESOS-EGRESOS'!E90 -> 40000
L40: FERNANDO | N40: =+'INGRESOS-EGRESOS'!E105 -> 6420960
F41: =SUM(F5:F38) -> 124460960 | G41: =SUM(G5:G38) -> 125801960 | L41: EL NORTE- DUPLEX | N41: =+DUPLEX!E8 -> 4200000
L42: EL NORTE- ENTRADAS | N42: 0
F43: =+F41-G41 -> -1341000 | L43: EL NORTE - ALOJAMIENTOS | N43: =+'NEGOCIADOS- EL NORTE'!E116 -> 16510000

Sheet DIVIDENDOS
B3: GUILLE | C3: COBRANZAS | D3: GASTOS | E3: SALDO
C4: =+ESCUELITAS!Z12+DUPLEX!O11 -> 17270000 | D4: =+'INGRESOS-EGRESOS'!Q22 -> 2849000 | E4: =+C4-D4 -> 14421000
B8: DIEGO | C8: COBRANZAS | D8: GASTOS | E8: SALDO
C9: =+ESCUELITAS!AA12+DUPLEX!P11 -> 11810000 | D9: =+'INGRESOS-EGRESOS'!R22 -> 1635000 | E9: =+C9-D9 -> 10175000
B15: FERNANDO | C15: COBRANZAS | D15: GASTOS | E15: SALDO
C16: =+ESCUELITAS!AB12+DUPLEX!Q11 -> 3320000 | D16: =+'INGRESOS-EGRESOS'!S22 -> 0 | E16: =+C16-D16 -> 3320000
